Workbook

Sheet HOWTO
A1: ABS_FPI_load_cases.xlsx —— 参数填写与代码生成说明
A3: 这个工作簿怎么用
A4: 1. Global Parameter 的 B 列：全局变量取值（所有 Case 共用）。
A5: 2. Local Parameter 从 E 列起：每个 Case 一列，右拉复制即可增加。
A6: 3. 改完参数后回到命令行执行：
A7: excel-codegen render -c <配置>.yaml -x ABS_FPI_load_cases.xlsx --write-excel
A8: 只想导出代码文件就换成 --outdir <目录>；只预览不写回则什么参数都不加。
A9: ★ 懒得开终端就双击本文件旁边的 ABS_FPI_load_cases_render.bat（Windows）或跑 ABS_FPI_load_cases_render.sh（Linux / macOS）。
A10: 想确认表里的代码是不是已经过期：excel-codegen check -c <配置>.yaml
A12: ★ 部分输出表是公式（engine: excel）：改参数后 Excel 打开即重算，不用跑脚本
A13: 公式支持占位符替换与行内分支（{% if %}）；要生成代码文件（--outdir）或做 CI 检查（check）仍需命令行。
A14: 不带 --write-excel 的 render 只预览，不会改变本文件。
... A32: EXT-T20.559-mu90-kf+1, EXT-T15-mu0-kf-1, EXT-T15-mu90-kf+1, WBT6-d8-mu90, WBT6-d15.059-mu0, WBT7-d20.559-mu90, COT1-d20.559-mu60

Sheet Global Parameter
A1: Variable | B1: Value | C1: Description | D1: Prefix | E1: Suffix
A2: L | B2: 340 | C2: 规范船长 [m]（3-1-1/3）；同时驱动 C_1 / k_lo / k_f | E2: m
A3: B | B3: 64 | C3: 规范型宽 [m]；B/2 决定舭部位置 | E3: m
A4: D | B4: 32 | C4: 规范型深 [m]（基线到甲板） | E4: m
A5: r_b | B5: 0.703 | C5: 舭圆半径 [m]：z_bilge = r_b，平底宽 = B/2 - r_b | E5: m
A6: freeboard | B6: 0.5 | C6: 甲板边线在载重线以上的余量 [m]；Fig. 10 的截断高度用它算 | E6: m
A7: rho_sea | B7: 1025 | C7: 海水密度 [kg/m^3]；规范下限 1.005 N/cm^2-m 即 1025 kg/m^3 | E7: kg/m^3
A8: g | B8: 9.81 | C8: 重力加速度 [m/s^2] | E8: m/s^2
A9: Cb | B9: 1 | C9: 方形系数 [-]（3-1-1/13.3）
A10: ax_x | B10: 1 | C10: 规范 x（自 AP）取自模型哪个轴：1=x, 2=y, 3=z
A11: ax_y | B11: 2 | C11: 规范 y（自中线，向右舷为正）取自模型哪个轴
A12: ax_z | B12: 3 | C12: 规范 z（基线以上，向上为正）取自模型哪个轴
A13: neg_x | C13: 规范 x 是否取反：填 - 表示取反，留空表示不取反
A14: neg_y | C14: 规范 y 是否取反：填 - 表示取反，留空表示不取反
A15: neg_z | C15: 规范 z 是否取反：填 - 表示取反，留空表示不取反
A16: d_f | B16: 20.559 | C16: 结构吃水 [m]；规范表按它给出，GM 四点表也按它插值 | E16: m
A17: rho_g_lo | B17: 10050 | C17: k_s = 0.878 对应的 rho g [N/m^3]（1.005 N/cm^2-m = 10050） | E17: N/m^3
A18: rho_g_hi | B18: 11180 | C18: k_s 达到 1.0 的 rho g [N/m^3]（1.118 N/cm^2-m = 11180） | E18: N/m^3

Sheet Local Parameter
A1: Variable | B1: Description | C1: Prefix | D1: Suffix | E1: EXT-T20.559-mu90-kf+1 | F1: EXT-T15-mu0-kf-1 | G1: EXT-T15-mu90-kf+1 | H1: WBT6-d8-mu90 | I1: WBT6-d15.059-mu0 | J1: WBT7-d20.559-mu90 | K1: COT1-d20.559-mu60
A2: kind | B2: 这个 Case 属于哪一套规则：EXT / INT（多规则集合用时用 case_filter 分流） | E2: EXT | F2: EXT | G2: EXT | H2: INT | I2: INT | J2: INT | K2: INT
A3: draft | B3: 工况吃水 [m]；h_s = draft - z，负值截断为 0 | D3: m | E3: 20.559 | F3: 15 | G3: 15 | H3: 8 | I3: 15.059 | J3: 20.559 | K3: 20.559
A4: mu_deg | B4: 浪向角 [deg]，0 = 顶浪，90 = 右舷来浪（Table 1A D） | D4: deg | E4: 90 | F4: 0 | G4: 90 | H4: 90 | I4: 0 | J4: 90 | K4: 60
A5: k_c | B5: 组合工况相关系数 [-]，进 h_de = k_c h_di（Table 1A B） | E5: 1 | F5: 0.5 | G5: 1 | H5: 1 | I5: 0.4 | J5: 1 | K5: 0.5
A6: k_f0 | B6: 相位因子 +1 / -1 [-]，决定参考站落在哪一端（Table 1A B） | E6: 1 | F6: -1 | G6: 1 | H6: 1 | I6: 1 | J6: 1 | K6: 1
A7: k_u | B7: 载荷系数 [-]；规范默认 1.0，1.1 用于板与纵骨的工况 | E7: 1.1 | F7: 1.1 | G7: 1.1 | H7: 1.1 | I7: 1.1 | J7: 1.1 | K7: 1.1
A8: beta_EPS | B8: 外压 ESF，右舷 [-]（5A-3-A1/3） | E8: 0.733 | F8: 0.733 | G8: 0.733 | H8: 0.733 | I8: 0.733 | J8: 0.733 | K8: 0.733
A9: beta_EPP | B9: 外压 ESF，左舷 [-]（5A-3-A1/3） | E9: 0.733 | F9: 0.733 | G9: 0.733 | H9: 0.733 | I9: 0.733 | J9: 0.733 | K9: 0.733
A10: k_esf | B10: 项目对 ESF 的分项系数 [-] | E10: 1.1 | F10: 1.1 | G10: 1.1 | H10: 1.1 | I10: 1.1 | J10: 1.1 | K10: 1.1
A11: x_o | B11: 参考站 [m]，自 AP 量起（Fig. 9 脚注） | D11: m | E11: 51 | F11: 51 | G11: 51 | H11: 51 | I11: 51 | J11: 51 | K11: 51
A12: beta_VAC | B12: 垂向加速度 ESF [-]（5A-3-A1/3） | E12: 0.66 | F12: 0.66 | G12: 0.66 | H12: 0.66 | I12: 0.66 | J12: 0.66 | K12: 0.66
A13: beta_LAC | B13: 纵向加速度 ESF [-] | E13: 0.758 | F13: 0.758 | G13: 0.758 | H13: 0.758 | I13: 0.758 | J13: 0.758 | K13: 0.758
A14: beta_TAC | B14: 横向加速度 ESF [-] | E14: 0.557 | F14: 0.557 | G14: 0.557 | H14: 0.557 | I14: 0.557 | J14: 0.557 | K14: 0.557
A15: beta_PMO | B15: 纵摇 ESF [-] | E15: 0.686 | F15: 0.686 | G15: 0.686 | H15: 0.686 | I15: 0.686 | J15: 0.686 | K15: 0.686
A16: beta_RMO | B16: 横摇 ESF [-] | E16: 0.492 | F16: 0.492 | G16: 0.492 | H16: 0.492 | I16: 0.492 | J16: 0.492 | K16: 0.492
A17: w_v | B17: 垂向加速度权重 [-]（Table 1A B） | E17: 0.75 | F17: 0.75 | G17: 0.75 | H17: 0.75 | I17: 0.75 | J17: 0.75 | K17: 0.75
A18: w_l | B18: 纵向加速度权重 [-] | E18: 0.25 | F18: 0.25 | G18: 0.25 | H18: 0.25 | I18: 0.25 | J18: 0.25 | K18: 0.25
A19: w_t | B19: 横向加速度权重 [-] | E19: 0.75 | F19: 0.75 | G19: 0.75 | H19: 0.75 | I19: 0.75 | J19: 0.75 | K19: 0.75
A20: xi | B20: 舱长方向参考位置 [m]（5.7.2(b)） | D20: m | E20: 21 | F20: 21 | G20: 21 | H20: 21 | I20: 21 | J20: 7.25 | K20: 21
A21: delta_b | B21: 舱宽方向修正 [m]（5.7.2(b)）；无则填 0 | D21: m | E21: 0 | F21: 0 | G21: 0 | H21: 0 | I21: 0 | J21: 0 | K21: 0
A22: delta_h | B22: 舱高方向修正 [m]（5.7.2(b)）；无则填 0 | D22: m | E22: 0 | F22: 0 | G22: 0 | H22: 0 | I22: 0 | J22: 0 | K22: 0
A23: tank_ref | B23: 本 Case 用哪个舱（成员表的行名） | E23: WBT6 | F23: WBT6 | G23: WBT6 | H23: WBT6 | I23: WBT6 | J23: WBT7 | K23: COT1

Sheet Tank Data
A1: 成员 | B1: rho_tank | C1: l_tank | D1: b_tank | E1: h_tank | F1: eta_deck | G1: eta_overflow | H1: C_dp | I1: C_ru | J1: p_vp | K1: GM_full_in | L1: k_r_in | M1: tank_is_ballast | N1: member_11_17
A2: WBT6 | B2: 1025 | C2: 42 | D2: 32 | E2: 32 | F2: 0 | G2: 0 | H2: 1 | I2: 1 | J2: 0 | K2: 0 | L2: 0 | M2: 1 | N2: 0
A3: WBT7 | B3: 1025 | C3: 14.5 | D3: 10.15 | E3: 32 | F3: 0 | G3: 0 | H3: 1 | I3: 1 | J3: 0 | K3: 0 | L3: 0 | M3: 1 | N3: 0
A4: COT1 | B4: 900 | C4: 42 | D4: 32 | E4: 32 | F4: 0 | G4: 0 | H4: 1 | I4: 1 | J4: 0.21 | K4: 0 | L4: 0 | M4: 0 | N4: 1

Sheet Code EXT
B1: EXT-T20.559-mu90-kf+1 | C1: EXT-T15-mu0-kf-1 | D1: EXT-T15-mu90-kf+1
B2: ="// "&'Local Parameter'!E$1 | C2: ="// "&'Local Parameter'!F$1 | D2: ="// "&'Local Parameter'!G$1
B3: ="// The rules live in the RULE frame: x from the A.P., y from the centre line" | C3: ="// The rules live in the RULE frame: x from the A.P., y from the centre line" | D3: ="// The rules live in the RULE frame: x from the A.P., y from the centre line"
B4: ="// positive starboard, z above the baseline. The model usually is not, so the" | C4: ="// positive starboard, z above the baseline. The model usually is not, so the" | D4: ="// positive starboard, z above the baseline. The model usually is not, so the"
B5: ="// three mapping cells (ax_* / neg_*) convert it. All three coordinates go" | C5: ="// three mapping cells (ax_* / neg_*) convert it. All three coordinates go" | D5: ="// three mapping cells (ax_* / neg_*) convert it. All three coordinates go"
B6: ="// through temporaries first: assigning them in place would read a coordinate" | C6: ="// through temporaries first: assigning them in place would read a coordinate" | D6: ="// through temporaries first: assigning them in place would read a coordinate"
B7: ="// that has already been overwritten." | C7: ="// that has already been overwritten." | D7: ="// that has already been overwritten."
B8: ="var t1 = x;" | C8: ="var t1 = x;" | D8: ="var t1 = x;"
B9: ="var t2 = y;" | C9: ="var t2 = y;" | D9: ="var t2 = y;"
B10: ="var t3 = z;" | C10: ="var t3 = z;" | D10: ="var t3 = z;"
B11: ="x = "&IF(ISBLANK(INDEX('Global Parameter'!$D:$D,MATCH("neg_x",'Global Parameter'!$A:$A,0))),"",INDEX('Global Parameter'!$D:$D,MATCH("neg_x",'Global Parameter'!$A:$A,0)))&IF(ISBLANK(INDEX('Global Parameter'!$B:$B,MATCH("neg_x",'Global Parameter'!$A:$A,0))),"",INDEX('Global Parameter'!$B:$B,MATCH("neg_x",'Global Parameter'!$A:$A,0)))&IF(ISBLANK(INDEX('Global Parameter'!$E:$E,MATCH("neg_x",'Global Parameter'!$A:$A,0))),"",INDEX('Global Parameter'!$E:$E,MATCH("neg_x",'Global Parameter'!$A:$A,0)))&"t"&IF(ISBLANK(INDEX('Global Parameter'!$D:$D,MATCH("ax_x",'Global Parameter'!$A:$A,0))),"",INDEX('Global Parameter'!$D:$D,MATCH("ax_x",'Global Parameter'!$A:$A,0)))&IF(ISBLANK(INDEX('Global Parameter'!$B:$B,MATCH("ax_x",'Global Parameter'!$A:$A,0))),"1",IF(INDEX('Global Parameter'!$B:$B,MATCH("ax_x",'Global Parameter'!$A:$A,0))="","1",INDEX('Global Parameter'!$B:$B,MATCH("ax_x",'Global Parameter'!$A:$A,0))))&IF(ISBLANK(INDEX('Global Parameter'!$E:$E,MATCH("ax_x",'Global Parameter'!$A:$A,0))),"",INDEX('Global Parameter'!$E:$E,MATCH("ax_x",'Global Parameter'!$A:$A,0)))&";" | C11: ="x = "&IF(ISBLANK(INDEX('Global Parameter'!$D:$D,MATCH("neg_x",'Global Parameter'!$A:$A,0))),"",INDEX('Global Parameter'!$D:$D,MATCH("neg_x",'Global Parameter'!$A:$A,0)))&IF(ISBLANK(INDEX('Global Parameter'!$B:$B,MATCH("neg_x",'Global Parameter'!$A:$A,0))),"",INDEX('Global Parameter'!$B:$B,MATCH("neg_x",'Global Parameter'!$A:$A,0)))&IF(ISBLANK(INDEX('Global Parameter'!$E:$E,MATCH("neg_x",'Global Parameter'!$A:$A,0))),"",INDEX('Global Parameter'!$E:$E,MATCH("neg_x",'Global Parameter'!$A:$A,0)))&"t"&IF(ISBLANK(INDEX('Global Parameter'!$D:$D,MATCH("ax_x",'Global Parameter'!$A:$A,0))),"",INDEX('Global Parameter'!$D:$D,MATCH("ax_x",'Global Parameter'!$A:$A,0)))&IF(ISBLANK(INDEX('Global Parameter'!$B:$B,MATCH("ax_x",'Global Parameter'!$A:$A,0))),"1",IF(INDEX('Global Parameter'!$B:$B,MATCH("ax_x",'Global Parameter'!$A:$A,0))="","1",INDEX('Global Parameter'!$B:$B,MATCH("ax_x",'Global Parameter'!$A:$A,0))))&IF(ISBLANK(INDEX('Global Parameter'!$E:$E,MATCH("ax_x",'Global Parameter'!$A:$A,0))),"",INDEX('Global Parameter'!$E:$E,MATCH("ax_x",'Global Parameter'!$A:$A,0)))&";" | D11: ="x = "&IF(ISBLANK(INDEX('Global Parameter'!$D:$D,MATCH("neg_x",'Global Parameter'!$A:$A,0))),"",INDEX('Global Parameter'!$D:$D,MATCH("neg_x",'Global Parameter'!$A:$A,0)))&IF(ISBLANK(INDEX('Global Parameter'!$B:$B,MATCH("neg_x",'Global Parameter'!$A:$A,0))),"",INDEX('Global Parameter'!$B:$B,MATCH("neg_x",'Global Parameter'!$A:$A,0)))&IF(ISBLANK(INDEX('Global Parameter'!$E:$E,MATCH("neg_x",'Global Parameter'!$A:$A,0))),"",INDEX('Global Parameter'!$E:$E,MATCH("neg_x",'Global Parameter'!$A:$A,0)))&"t"&IF(ISBLANK(INDEX('Global Parameter'!$D:$D,MATCH("ax_x",'Global Parameter'!$A:$A,0))),"",INDEX('Global Parameter'!$D:$D,MATCH("ax_x",'Global Parameter'!$A:$A,0)))&IF(ISBLANK(INDEX('Global Parameter'!$B:$B,MATCH("ax_x",'Global Parameter'!$A:$A,0))),"1",IF(INDEX('Global Parameter'!$B:$B,MATCH("ax_x",'Global Parameter'!$A:$A,0))="","1",INDEX('Global Parameter'!$B:$B,MATCH("ax_x",'Global Parameter'!$A:$A,0))))&IF(ISBLANK(INDEX('Global Parameter'!$E:$E,MATCH("ax_x",'Global Parameter'!$A:$A,0))),"",INDEX('Global Parameter'!$E:$E,MATCH("ax_x",'Global Parameter'!$A:$A,0)))&";"
B12: ="y = "&IF(ISBLANK(INDEX('Global Parameter'!$D:$D,MATCH("neg_y",'Global Parameter'!$A:$A,0))),"",INDEX('Global Parameter'!$D:$D,MATCH("neg_y",'Global Parameter'!$A:$A,0)))&IF(ISBLANK(INDEX('Global Parameter'!$B:$B,MATCH("neg_y",'Global Parameter'!$A:$A,0))),"",INDEX('Global Parameter'!$B:$B,MATCH("neg_y",'Global Parameter'!$A:$A,0)))&IF(ISBLANK(INDEX('Global Parameter'!$E:$E,MATCH("neg_y",'Global Parameter'!$A:$A,0))),"",INDEX('Global Parameter'!$E:$E,MATCH("neg_y",'Global Parameter'!$A:$A,0)))&"t"&IF(ISBLANK(INDEX('Global Parameter'!$D:$D,MATCH("ax_y",'Global Parameter'!$A:$A,0))),"",INDEX('Global Parameter'!$D:$D,MATCH("ax_y",'Global Parameter'!$A:$A,0)))&IF(ISBLANK(INDEX('Global Parameter'!$B:$B,MATCH("ax_y",'Global Parameter'!$A:$A,0))),"2",IF(INDEX('Global Parameter'!$B:$B,MATCH("ax_y",'Global Parameter'!$A:$A,0))="","2",INDEX('Global Parameter'!$B:$B,MATCH("ax_y",'Global Parameter'!$A:$A,0))))&IF(ISBLANK(INDEX('Global Parameter'!$E:$E,MATCH("ax_y",'Global Parameter'!$A:$A,0))),"",INDEX('Global Parameter'!$E:$E,MATCH("ax_y",'Global Parameter'!$A:$A,0)))&";" | C12: ="y = "&IF(ISBLANK(INDEX('Global Parameter'!$D:$D,MATCH("neg_y",'Global Parameter'!$A:$A,0))),"",INDEX('Global Parameter'!$D:$D,MATCH("neg_y",'Global Parameter'!$A:$A,0)))&IF(ISBLANK(INDEX('Global Parameter'!$B:$B,MATCH("neg_y",'Global Parameter'!$A:$A,0))),"",INDEX('Global Parameter'!$B:$B,MATCH("neg_y",'Global Parameter'!$A:$A,0)))&IF(ISBLANK(INDEX('Global Parameter'!$E:$E,MATCH("neg_y",'Global Parameter'!$A:$A,0))),"",INDEX('Global Parameter'!$E:$E,MATCH("neg_y",'Global Parameter'!$A:$A,0)))&"t"&IF(ISBLANK(INDEX('Global Parameter'!$D:$D,MATCH("ax_y",'Global Parameter'!$A:$A,0))),"",INDEX('Global Parameter'!$D:$D,MATCH("ax_y",'Global Parameter'!$A:$A,0)))&IF(ISBLANK(INDEX('Global Parameter'!$B:$B,MATCH("ax_y",'Global Parameter'!$A:$A,0))),"2",IF(INDEX('Global Parameter'!$B:$B,MATCH("ax_y",'Global Parameter'!$A:$A,0))="","2",INDEX('Global Parameter'!$B:$B,MATCH("ax_y",'Global Parameter'!$A:$A,0))))&IF(ISBLANK(INDEX('Global Parameter'!$E:$E,MATCH("ax_y",'Global Parameter'!$A:$A,0))),"",INDEX('Global Parameter'!$E:$E,MATCH("ax_y",'Global Parameter'!$A:$A,0)))&";" | D12: ="y = "&IF(ISBLANK(INDEX('Global Parameter'!$D:$D,MATCH("neg_y",'Global Parameter'!$A:$A,0))),"",INDEX('Global Parameter'!$D:$D,MATCH("neg_y",'Global Parameter'!$A:$A,0)))&IF(ISBLANK(INDEX('Global Parameter'!$B:$B,MATCH("neg_y",'Global Parameter'!$A:$A,0))),"",INDEX('Global Parameter'!$B:$B,MATCH("neg_y",'Global Parameter'!$A:$A,0)))&IF(ISBLANK(INDEX('Global Parameter'!$E:$E,MATCH("neg_y",'Global Parameter'!$A:$A,0))),"",INDEX('Global Parameter'!$E:$E,MATCH("neg_y",'Global Parameter'!$A:$A,0)))&"t"&IF(ISBLANK(INDEX('Global Parameter'!$D:$D,MATCH("ax_y",'Global Parameter'!$A:$A,0))),"",INDEX('Global Parameter'!$D:$D,MATCH("ax_y",'Global Parameter'!$A:$A,0)))&IF(ISBLANK(INDEX('Global Parameter'!$B:$B,MATCH("ax_y",'Global Parameter'!$A:$A,0))),"2",IF(INDEX('Global Parameter'!$B:$B,MATCH("ax_y",'Global Parameter'!$A:$A,0))="","2",INDEX('Global Parameter'!$B:$B,MATCH("ax_y",'Global Parameter'!$A:$A,0))))&IF(ISBLANK(INDEX('Global Parameter'!$E:$E,MATCH("ax_y",'Global Parameter'!$A:$A,0))),"",INDEX('Global Parameter'!$E:$E,MATCH("ax_y",'Global Parameter'!$A:$A,0)))&";"
B13: ="z = "&IF(ISBLANK(INDEX('Global Parameter'!$D:$D,MATCH("neg_z",'Global Parameter'!$A:$A,0))),"",INDEX('Global Parameter'!$D:$D,MATCH("neg_z",'Global Parameter'!$A:$A,0)))&IF(ISBLANK(INDEX('Global Parameter'!$B:$B,MATCH("neg_z",'Global Parameter'!$A:$A,0))),"",INDEX('Global Parameter'!$B:$B,MATCH("neg_z",'Global Parameter'!$A:$A,0)))&IF(ISBLANK(INDEX('Global Parameter'!$E:$E,MATCH("neg_z",'Global Parameter'!$A:$A,0))),"",INDEX('Global Parameter'!$E:$E,MATCH("neg_z",'Global Parameter'!$A:$A,0)))&"t"&IF(ISBLANK(INDEX('Global Parameter'!$D:$D,MATCH("ax_z",'Global Parameter'!$A:$A,0))),"",INDEX('Global Parameter'!$D:$D,MATCH("ax_z",'Global Parameter'!$A:$A,0)))&IF(ISBLANK(INDEX('Global Parameter'!$B:$B,MATCH("ax_z",'Global Parameter'!$A:$A,0))),"3",IF(INDEX('Global Parameter'!$B:$B,MATCH("ax_z",'Global Parameter'!$A:$A,0))="","3",INDEX('Global Parameter'!$B:$B,MATCH("ax_z",'Global Parameter'!$A:$A,0))))&IF(ISBLANK(INDEX('Global Parameter'!$E:$E,MATCH("ax_z",'Global Parameter'!$A:$A,0))),"",INDEX('Global Parameter'!$E:$E,MATCH("ax_z",'Global Parameter'!$A:$A,0)))&";" | C13: ="z = "&IF(ISBLANK(INDEX('Global Parameter'!$D:$D,MATCH("neg_z",'Global Parameter'!$A:$A,0))),"",INDEX('Global Parameter'!$D:$D,MATCH("neg_z",'Global Parameter'!$A:$A,0)))&IF(ISBLANK(INDEX('Global Parameter'!$B:$B,MATCH("neg_z",'Global Parameter'!$A:$A,0))),"",INDEX('Global Parameter'!$B:$B,MATCH("neg_z",'Global Parameter'!$A:$A,0)))&IF(ISBLANK(INDEX('Global Parameter'!$E:$E,MATCH("neg_z",'Global Parameter'!$A:$A,0))),"",INDEX('Global Parameter'!$E:$E,MATCH("neg_z",'Global Parameter'!$A:$A,0)))&"t"&IF(ISBLANK(INDEX('Global Parameter'!$D:$D,MATCH("ax_z",'Global Parameter'!$A:$A,0))),"",INDEX('Global Parameter'!$D:$D,MATCH("ax_z",'Global Parameter'!$A:$A,0)))&IF(ISBLANK(INDEX('Global Parameter'!$B:$B,MATCH("ax_z",'Global Parameter'!$A:$A,0))),"3",IF(INDEX('Global Parameter'!$B:$B,MATCH("ax_z",'Global Parameter'!$A:$A,0))="","3",INDEX('Global Parameter'!$B:$B,MATCH("ax_z",'Global Parameter'!$A:$A,0))))&IF(ISBLANK(INDEX('Global Parameter'!$E:$E,MATCH("ax_z",'Global Parameter'!$A:$A,0))),"",INDEX('Global Parameter'!$E:$E,MATCH("ax_z",'Global Parameter'!$A:$A,0)))&";" | D13: ="z = "&IF(ISBLANK(INDEX('Global Parameter'!$D:$D,MATCH("neg_z",'Global Parameter'!$A:$A,0))),"",INDEX('Global Parameter'!$D:$D,MATCH("neg_z",'Global Parameter'!$A:$A,0)))&IF(ISBLANK(INDEX('Global Parameter'!$B:$B,MATCH("neg_z",'Global Parameter'!$A:$A,0))),"",INDEX('Global Parameter'!$B:$B,MATCH("neg_z",'Global Parameter'!$A:$A,0)))&IF(ISBLANK(INDEX('Global Parameter'!$E:$E,MATCH("neg_z",'Global Parameter'!$A:$A,0))),"",INDEX('Global Parameter'!$E:$E,MATCH("neg_z",'Global Parameter'!$A:$A,0)))&"t"&IF(ISBLANK(INDEX('Global Parameter'!$D:$D,MATCH("ax_z",'Global Parameter'!$A:$A,0))),"",INDEX('Global Parameter'!$D:$D,MATCH("ax_z",'Global Parameter'!$A:$A,0)))&IF(ISBLANK(INDEX('Global Parameter'!$B:$B,MATCH("ax_z",'Global Parameter'!$A:$A,0))),"3",IF(INDEX('Global Parameter'!$B:$B,MATCH("ax_z",'Global Parameter'!$A:$A,0))="","3",INDEX('Global Parameter'!$B:$B,MATCH("ax_z",'Global Parameter'!$A:$A,0))))&IF(ISBLANK(INDEX('Global Parameter'!$E:$E,MATCH("ax_z",'Global Parameter'!$A:$A,0))),"",INDEX('Global Parameter'!$E:$E,MATCH("ax_z",'Global Parameter'!$A:$A,0)))&";"
B14: ="// --- global parameters (same for every case)" | C14: ="// --- global parameters (same for every case)" | D14: ="// --- global parameters (same for every case)"
B15: ="var L = "&IF(ISBLANK(INDEX('Global Parameter'!$D:$D,MATCH("L",'Global Parameter'!$A:$A,0))),"",INDEX('Global Parameter'!$D:$D,MATCH("L",'Global Parameter'!$A:$A,0)))&IF(ISBLANK(INDEX('Global Parameter'!$B:$B,MATCH("L",'Global Parameter'!$A:$A,0))),340,IF(INDEX('Global Parameter'!$B:$B,MATCH("L",'Global Parameter'!$A:$A,0))="",340,INDEX('Global Parameter'!$B:$B,MATCH("L",'Global Parameter'!$A:$A,0))))&IF(ISBLANK(INDEX('Global Parameter'!$E:$E,MATCH("L",'Global Parameter'!$A:$A,0)))," m",IF(INDEX('Global Parameter'!$E:$E,MATCH("L",'Global Parameter'!$A:$A,0))=""," m",INDEX('Global Parameter'!$E:$E,MATCH("L",'Global Parameter'!$A:$A,0))))&";" | C15: ="var L = "&IF(ISBLANK(INDEX('Global Parameter'!$D:$D,MATCH("L",'Global Parameter'!$A:$A,0))),"",INDEX('Global Parameter'!$D:$D,MATCH("L",'Global Parameter'!$A:$A,0)))&IF(ISBLANK(INDEX('Global Parameter'!$B:$B,MATCH("L",'Global Parameter'!$A:$A,0))),340,IF(INDEX('Global Parameter'!$B:$B,MATCH("L",'Global Parameter'!$A:$A,0))="",340,INDEX('Global Parameter'!$B:$B,MATCH("L",'Global Parameter'!$A:$A,0))))&IF(ISBLANK(INDEX('Global Parameter'!$E:$E,MATCH("L",'Global Parameter'!$A:$A,0)))," m",IF(INDEX('Global Parameter'!$E:$E,MATCH("L",'Global Parameter'!$A:$A,0))=""," m",INDEX('Global Parameter'!$E:$E,MATCH("L",'Global Parameter'!$A:$A,0))))&";" | D15: ="var L = "&IF(ISBLANK(INDEX('Global Parameter'!$D:$D,MATCH("L",'Global Parameter'!$A:$A,0))),"",INDEX('Global Parameter'!$D:$D,MATCH("L",'Global Parameter'!$A:$A,0)))&IF(ISBLANK(INDEX('Global Parameter'!$B:$B,MATCH("L",'Global Parameter'!$A:$A,0))),340,IF(INDEX('Global Parameter'!$B:$B,MATCH("L",'Global Parameter'!$A:$A,0))="",340,INDEX('Global Parameter'!$B:$B,MATCH("L",'Global Parameter'!$A:$A,0))))&IF(ISBLANK(INDEX('Global Parameter'!$E:$E,MATCH("L",'Global Parameter'!$A:$A,0)))," m",IF(INDEX('Global Parameter'!$E:$E,MATCH("L",'Global Parameter'!$A:$A,0))=""," m",INDEX('Global Parameter'!$E:$E,MATCH("L",'Global Parameter'!$A:$A,0))))&";"
B16: ="var B = "&IF(ISBLANK(INDEX('Global Parameter'!$D:$D,MATCH("B",'Global Parameter'!$A:$A,0))),"",INDEX('Global Parameter'!$D:$D,MATCH("B",'Global Parameter'!$A:$A,0)))&IF(ISBLANK(INDEX('Global Parameter'!$B:$B,MATCH("B",'Global Parameter'!$A:$A,0))),64,IF(INDEX('Global Parameter'!$B:$B,MATCH("B",'Global Parameter'!$A:$A,0))="",64,INDEX('Global Parameter'!$B:$B,MATCH("B",'Global Parameter'!$A:$A,0))))&IF(ISBLANK(INDEX('Global Parameter'!$E:$E,MATCH("B",'Global Parameter'!$A:$A,0)))," m",IF(INDEX('Global Parameter'!$E:$E,MATCH("B",'Global Parameter'!$A:$A,0))=""," m",INDEX('Global Parameter'!$E:$E,MATCH("B",'Global Parameter'!$A:$A,0))))&";" | C16: ="var B = "&IF(ISBLANK(INDEX('Global Parameter'!$D:$D,MATCH("B",'Global Parameter'!$A:$A,0))),"",INDEX('Global Parameter'!$D:$D,MATCH("B",'Global Parameter'!$A:$A,0)))&IF(ISBLANK(INDEX('Global Parameter'!$B:$B,MATCH("B",'Global Parameter'!$A:$A,0))),64,IF(INDEX('Global Parameter'!$B:$B,MATCH("B",'Global Parameter'!$A:$A,0))="",64,INDEX('Global Parameter'!$B:$B,MATCH("B",'Global Parameter'!$A:$A,0))))&IF(ISBLANK(INDEX('Global Parameter'!$E:$E,MATCH("B",'Global Parameter'!$A:$A,0)))," m",IF(INDEX('Global Parameter'!$E:$E,MATCH("B",'Global Parameter'!$A:$A,0))=""," m",INDEX('Global Parameter'!$E:$E,MATCH("B",'Global Parameter'!$A:$A,0))))&";" | D16: ="var B = "&IF(ISBLANK(INDEX('Global Parameter'!$D:$D,MATCH("B",'Global Parameter'!$A:$A,0))),"",INDEX('Global Parameter'!$D:$D,MATCH("B",'Global Parameter'!$A:$A,0)))&IF(ISBLANK(INDEX('Global Parameter'!$B:$B,MATCH("B",'Global Parameter'!$A:$A,0))),64,IF(INDEX('Global Parameter'!$B:$B,MATCH("B",'Global Parameter'!$A:$A,0))="",64,INDEX('Global Parameter'!$B:$B,MATCH("B",'Global Parameter'!$A:$A,0))))&IF(ISBLANK(INDEX('Global Parameter'!$E:$E,MATCH("B",'Global Parameter'!$A:$A,0)))," m",IF(INDEX('Global Parameter'!$E:$E,MATCH("B",'Global Parameter'!$A:$A,0))=""," m",INDEX('Global Parameter'!$E:$E,MATCH("B",'Global Parameter'!$A:$A,0))))&";"
B17: ="var D = "&IF(ISBLANK(INDEX('Global Parameter'!$D:$D,MATCH("D",'Global Parameter'!$A:$A,0))),"",INDEX('Global Parameter'!$D:$D,MATCH("D",'Global Parameter'!$A:$A,0)))&IF(ISBLANK(INDEX('Global Parameter'!$B:$B,MATCH("D",'Global Parameter'!$A:$A,0))),32,IF(INDEX('Global Parameter'!$B:$B,MATCH("D",'Global Parameter'!$A:$A,0))="",32,INDEX('Global Parameter'!$B:$B,MATCH("D",'Global Parameter'!$A:$A,0))))&IF(ISBLANK(INDEX('Global Parameter'!$E:$E,MATCH("D",'Global Parameter'!$A:$A,0)))," m",IF(INDEX('Global Parameter'!$E:$E,MATCH("D",'Global Parameter'!$A:$A,0))=""," m",INDEX('Global Parameter'!$E:$E,MATCH("D",'Global Parameter'!$A:$A,0))))&";" | C17: ="var D = "&IF(ISBLANK(INDEX('Global Parameter'!$D:$D,MATCH("D",'Global Parameter'!$A:$A,0))),"",INDEX('Global Parameter'!$D:$D,MATCH("D",'Global Parameter'!$A:$A,0)))&IF(ISBLANK(INDEX('Global Parameter'!$B:$B,MATCH("D",'Global Parameter'!$A:$A,0))),32,IF(INDEX('Global Parameter'!$B:$B,MATCH("D",'Global Parameter'!$A:$A,0))="",32,INDEX('Global Parameter'!$B:$B,MATCH("D",'Global Parameter'!$A:$A,0))))&IF(ISBLANK(INDEX('Global Parameter'!$E:$E,MATCH("D",'Global Parameter'!$A:$A,0)))," m",IF(INDEX('Global Parameter'!$E:$E,MATCH("D",'Global Parameter'!$A:$A,0))=""," m",INDEX('Global Parameter'!$E:$E,MATCH("D",'Global Parameter'!$A:$A,0))))&";" | D17: ="var D = "&IF(ISBLANK(INDEX('Global Parameter'!$D:$D,MATCH("D",'Global Parameter'!$A:$A,0))),"",INDEX('Global Parameter'!$D:$D,MATCH("D",'Global Parameter'!$A:$A,0)))&IF(ISBLANK(INDEX('Global Parameter'!$B:$B,MATCH("D",'Global Parameter'!$A:$A,0))),32,IF(INDEX('Global Parameter'!$B:$B,MATCH("D",'Global Parameter'!$A:$A,0))="",32,INDEX('Global Parameter'!$B:$B,MATCH("D",'Global Parameter'!$A:$A,0))))&IF(ISBLANK(INDEX('Global Parameter'!$E:$E,MATCH("D",'Global Parameter'!$A:$A,0)))," m",IF(INDEX('Global Parameter'!$E:$E,MATCH("D",'Global Parameter'!$A:$A,0))=""," m",INDEX('Global Parameter'!$E:$E,MATCH("D",'Global Parameter'!$A:$A,0))))&";"
B18: ="var r_b = "&IF(ISBLANK(INDEX('Global Parameter'!$D:$D,MATCH("r_b",'Global Parameter'!$A:$A,0))),"",INDEX('Global Parameter'!$D:$D,MATCH("r_b",'Global Parameter'!$A:$A,0)))&IF(ISBLANK(INDEX('Global Parameter'!$B:$B,MATCH("r_b",'Global Parameter'!$A:$A,0))),0.703,IF(INDEX('Global Parameter'!$B:$B,MATCH("r_b",'Global Parameter'!$A:$A,0))="",0.703,INDEX('Global Parameter'!$B:$B,MATCH("r_b",'Global Parameter'!$A:$A,0))))&IF(ISBLANK(INDEX('Global Parameter'!$E:$E,MATCH("r_b",'Global Parameter'!$A:$A,0)))," m",IF(INDEX('Global Parameter'!$E:$E,MATCH("r_b",'Global Parameter'!$A:$A,0))=""," m",INDEX('Global Parameter'!$E:$E,MATCH("r_b",'Global Parameter'!$A:$A,0))))&";" | C18: ="var r_b = "&IF(ISBLANK(INDEX('Global Parameter'!$D:$D,MATCH("r_b",'Global Parameter'!$A:$A,0))),"",INDEX('Global Parameter'!$D:$D,MATCH("r_b",'Global Parameter'!$A:$A,0)))&IF(ISBLANK(INDEX('Global Parameter'!$B:$B,MATCH("r_b",'Global Parameter'!$A:$A,0))),0.703,IF(INDEX('Global Parameter'!$B:$B,MATCH("r_b",'Global Parameter'!$A:$A,0))="",0.703,INDEX('Global Parameter'!$B:$B,MATCH("r_b",'Global Parameter'!$A:$A,0))))&IF(ISBLANK(INDEX('Global Parameter'!$E:$E,MATCH("r_b",'Global Parameter'!$A:$A,0)))," m",IF(INDEX('Global Parameter'!$E:$E,MATCH("r_b",'Global Parameter'!$A:$A,0))=""," m",INDEX('Global Parameter'!$E:$E,MATCH("r_b",'Global Parameter'!$A:$A,0))))&";" | D18: ="var r_b = "&IF(ISBLANK(INDEX('Global Parameter'!$D:$D,MATCH("r_b",'Global Parameter'!$A:$A,0))),"",INDEX('Global Parameter'!$D:$D,MATCH("r_b",'Global Parameter'!$A:$A,0)))&IF(ISBLANK(INDEX('Global Parameter'!$B:$B,MATCH("r_b",'Global Parameter'!$A:$A,0))),0.703,IF(INDEX('Global Parameter'!$B:$B,MATCH("r_b",'Global Parameter'!$A:$A,0))="",0.703,INDEX('Global Parameter'!$B:$B,MATCH("r_b",'Global Parameter'!$A:$A,0))))&IF(ISBLANK(INDEX('Global Parameter'!$E:$E,MATCH("r_b",'Global Parameter'!$A:$A,0)))," m",IF(INDEX('Global Parameter'!$E:$E,MATCH("r_b",'Global Parameter'!$A:$A,0))=""," m",INDEX('Global Parameter'!$E:$E,MATCH("r_b",'Global Parameter'!$A:$A,0))))&";"
B19: ="var freeboard = "&IF(ISBLANK(INDEX('Global Parameter'!$D:$D,MATCH("freeboard",'Global Parameter'!$A:$A,0))),"",INDEX('Global Parameter'!$D:$D,MATCH("freeboard",'Global Parameter'!$A:$A,0)))&IF(ISBLANK(INDEX('Global Parameter'!$B:$B,MATCH("freeboard",'Global Parameter'!$A:$A,0))),0.5,IF(INDEX('Global Parameter'!$B:$B,MATCH("freeboard",'Global Parameter'!$A:$A,0))="",0.5,INDEX('Global Parameter'!$B:$B,MATCH("freeboard",'Global Parameter'!$A:$A,0))))&IF(ISBLANK(INDEX('Global Parameter'!$E:$E,MATCH("freeboard",'Global Parameter'!$A:$A,0)))," m",IF(INDEX('Global Parameter'!$E:$E,MATCH("freeboard",'Global Parameter'!$A:$A,0))=""," m",INDEX('Global Parameter'!$E:$E,MATCH("freeboard",'Global Parameter'!$A:$A,0))))&";" | C19: ="var freeboard = "&IF(ISBLANK(INDEX('Global Parameter'!$D:$D,MATCH("freeboard",'Global Parameter'!$A:$A,0))),"",INDEX('Global Parameter'!$D:$D,MATCH("freeboard",'Global Parameter'!$A:$A,0)))&IF(ISBLANK(INDEX('Global Parameter'!$B:$B,MATCH("freeboard",'Global Parameter'!$A:$A,0))),0.5,IF(INDEX('Global Parameter'!$B:$B,MATCH("freeboard",'Global Parameter'!$A:$A,0))="",0.5,INDEX('Global Parameter'!$B:$B,MATCH("freeboard",'Global Parameter'!$A:$A,0))))&IF(ISBLANK(INDEX('Global Parameter'!$E:$E,MATCH("freeboard",'Global Parameter'!$A:$A,0)))," m",IF(INDEX('Global Parameter'!$E:$E,MATCH("freeboard",'Global Parameter'!$A:$A,0))=""," m",INDEX('Global Parameter'!$E:$E,MATCH("freeboard",'Global Parameter'!$A:$A,0))))&";" | D19: ="var freeboard = "&IF(ISBLANK(INDEX('Global Parameter'!$D:$D,MATCH("freeboard",'Global Parameter'!$A:$A,0))),"",INDEX('Global Parameter'!$D:$D,MATCH("freeboard",'Global Parameter'!$A:$A,0)))&IF(ISBLANK(INDEX('Global Parameter'!$B:$B,MATCH("freeboard",'Global Parameter'!$A:$A,0))),0.5,IF(INDEX('Global Parameter'!$B:$B,MATCH("freeboard",'Global Parameter'!$A:$A,0))="",0.5,INDEX('Global Parameter'!$B:$B,MATCH("freeboard",'Global Parameter'!$A:$A,0))))&IF(ISBLANK(INDEX('Global Parameter'!$E:$E,MATCH("freeboard",'Global Parameter'!$A:$A,0)))," m",IF(INDEX('Global Parameter'!$E:$E,MATCH("freeboard",'Global Parameter'!$A:$A,0))=""," m",INDEX('Global Parameter'!$E:$E,MATCH("freeboard",'Global Parameter'!$A:$A,0))))&";"
B20: ="var rho_sea = "&IF(ISBLANK(INDEX('Global Parameter'!$D:$D,MATCH("rho_sea",'Global Parameter'!$A:$A,0))),"",INDEX('Global Parameter'!$D:$D,MATCH("rho_sea",'Global Parameter'!$A:$A,0)))&IF(ISBLANK(INDEX('Global Parameter'!$B:$B,MATCH("rho_sea",'Global Parameter'!$A:$A,0))),1025,IF(INDEX('Global Parameter'!$B:$B,MATCH("rho_sea",'Global Parameter'!$A:$A,0))="",1025,INDEX('Global Parameter'!$B:$B,MATCH("rho_sea",'Global Parameter'!$A:$A,0))))&IF(ISBLANK(INDEX('Global Parameter'!$E:$E,MATCH("rho_sea",'Global Parameter'!$A:$A,0)))," kg/m^3",IF(INDEX('Global Parameter'!$E:$E,MATCH("rho_sea",'Global Parameter'!$A:$A,0))=""," kg/m^3",INDEX('Global Parameter'!$E:$E,MATCH("rho_sea",'Global Parameter'!$A:$A,0))))&";" | C20: ="var rho_sea = "&IF(ISBLANK(INDEX('Global Parameter'!$D:$D,MATCH("rho_sea",'Global Parameter'!$A:$A,0))),"",INDEX('Global Parameter'!$D:$D,MATCH("rho_sea",'Global Parameter'!$A:$A,0)))&IF(ISBLANK(INDEX('Global Parameter'!$B:$B,MATCH("rho_sea",'Global Parameter'!$A:$A,0))),1025,IF(INDEX('Global Parameter'!$B:$B,MATCH("rho_sea",'Global Parameter'!$A:$A,0))="",1025,INDEX('Global Parameter'!$B:$B,MATCH("rho_sea",'Global Parameter'!$A:$A,0))))&IF(ISBLANK(INDEX('Global Parameter'!$E:$E,MATCH("rho_sea",'Global Parameter'!$A:$A,0)))," kg/m^3",IF(INDEX('Global Parameter'!$E:$E,MATCH("rho_sea",'Global Parameter'!$A:$A,0))=""," kg/m^3",INDEX('Global Parameter'!$E:$E,MATCH("rho_sea",'Global Parameter'!$A:$A,0))))&";" | D20: ="var rho_sea = "&IF(ISBLANK(INDEX('Global Parameter'!$D:$D,MATCH("rho_sea",'Global Parameter'!$A:$A,0))),"",INDEX('Global Parameter'!$D:$D,MATCH("rho_sea",'Global Parameter'!$A:$A,0)))&IF(ISBLANK(INDEX('Global Parameter'!$B:$B,MATCH("rho_sea",'Global Parameter'!$A:$A,0))),1025,IF(INDEX('Global Parameter'!$B:$B,MATCH("rho_sea",'Global Parameter'!$A:$A,0))="",1025,INDEX('Global Parameter'!$B:$B,MATCH("rho_sea",'Global Parameter'!$A:$A,0))))&IF(ISBLANK(INDEX('Global Parameter'!$E:$E,MATCH("rho_sea",'Global Parameter'!$A:$A,0)))," kg/m^3",IF(INDEX('Global Parameter'!$E:$E,MATCH("rho_sea",'Global Parameter'!$A:$A,0))=""," kg/m^3",INDEX('Global Parameter'!$E:$E,MATCH("rho_sea",'Global Parameter'!$A:$A,0))))&";"
B21: ="var g = "&IF(ISBLANK(INDEX('Global Parameter'!$D:$D,MATCH("g",'Global Parameter'!$A:$A,0))),"",INDEX('Global Parameter'!$D:$D,MATCH("g",'Global Parameter'!$A:$A,0)))&IF(ISBLANK(INDEX('Global Parameter'!$B:$B,MATCH("g",'Global Parameter'!$A:$A,0))),9.81,IF(INDEX('Global Parameter'!$B:$B,MATCH("g",'Global Parameter'!$A:$A,0))="",9.81,INDEX('Global Parameter'!$B:$B,MATCH("g",'Global Parameter'!$A:$A,0))))&IF(ISBLANK(INDEX('Global Parameter'!$E:$E,MATCH("g",'Global Parameter'!$A:$A,0)))," m/s^2",IF(INDEX('Global Parameter'!$E:$E,MATCH("g",'Global Parameter'!$A:$A,0))=""," m/s^2",INDEX('Global Parameter'!$E:$E,MATCH("g",'Global Parameter'!$A:$A,0))))&";" | C21: ="var g = "&IF(ISBLANK(INDEX('Global Parameter'!$D:$D,MATCH("g",'Global Parameter'!$A:$A,0))),"",INDEX('Global Parameter'!$D:$D,MATCH("g",'Global Parameter'!$A:$A,0)))&IF(ISBLANK(INDEX('Global Parameter'!$B:$B,MATCH("g",'Global Parameter'!$A:$A,0))),9.81,IF(INDEX('Global Parameter'!$B:$B,MATCH("g",'Global Parameter'!$A:$A,0))="",9.81,INDEX('Global Parameter'!$B:$B,MATCH("g",'Global Parameter'!$A:$A,0))))&IF(ISBLANK(INDEX('Global Parameter'!$E:$E,MATCH("g",'Global Parameter'!$A:$A,0)))," m/s^2",IF(INDEX('Global Parameter'!$E:$E,MATCH("g",'Global Parameter'!$A:$A,0))=""," m/s^2",INDEX('Global Parameter'!$E:$E,MATCH("g",'Global Parameter'!$A:$A,0))))&";" | D21: ="var g = "&IF(ISBLANK(INDEX('Global Parameter'!$D:$D,MATCH("g",'Global Parameter'!$A:$A,0))),"",INDEX('Global Parameter'!$D:$D,MATCH("g",'Global Parameter'!$A:$A,0)))&IF(ISBLANK(INDEX('Global Parameter'!$B:$B,MATCH("g",'Global Parameter'!$A:$A,0))),9.81,IF(INDEX('Global Parameter'!$B:$B,MATCH("g",'Global Parameter'!$A:$A,0))="",9.81,INDEX('Global Parameter'!$B:$B,MATCH("g",'Global Parameter'!$A:$A,0))))&IF(ISBLANK(INDEX('Global Parameter'!$E:$E,MATCH("g",'Global Parameter'!$A:$A,0)))," m/s^2",IF(INDEX('Global Parameter'!$E:$E,MATCH("g",'Global Parameter'!$A:$A,0))=""," m/s^2",INDEX('Global Parameter'!$E:$E,MATCH("g",'Global Parameter'!$A:$A,0))))&";"
B22: ="var Cb = "&IF(ISBLANK(INDEX('Global Parameter'!$D:$D,MATCH("Cb",'Global Parameter'!$A:$A,0))),"",INDEX('Global Parameter'!$D:$D,MATCH("Cb",'Global Parameter'!$A:$A,0)))&IF(ISBLANK(INDEX('Global Parameter'!$B:$B,MATCH("Cb",'Global Parameter'!$A:$A,0))),1,IF(INDEX('Global Parameter'!$B:$B,MATCH("Cb",'Global Parameter'!$A:$A,0))="",1,INDEX('Global Parameter'!$B:$B,MATCH("Cb",'Global Parameter'!$A:$A,0))))&IF(ISBLANK(INDEX('Global Parameter'!$E:$E,MATCH("Cb",'Global Parameter'!$A:$A,0))),"",INDEX('Global Parameter'!$E:$E,MATCH("Cb",'Global Parameter'!$A:$A,0)))&";" | C22: ="var Cb = "&IF(ISBLANK(INDEX('Global Parameter'!$D:$D,MATCH("Cb",'Global Parameter'!$A:$A,0))),"",INDEX('Global Parameter'!$D:$D,MATCH("Cb",'Global Parameter'!$A:$A,0)))&IF(ISBLANK(INDEX('Global Parameter'!$B:$B,MATCH("Cb",'Global Parameter'!$A:$A,0))),1,IF(INDEX('Global Parameter'!$B:$B,MATCH("Cb",'Global Parameter'!$A:$A,0))="",1,INDEX('Global Parameter'!$B:$B,MATCH("Cb",'Global Parameter'!$A:$A,0))))&IF(ISBLANK(INDEX('Global Parameter'!$E:$E,MATCH("Cb",'Global Parameter'!$A:$A,0))),"",INDEX('Global Parameter'!$E:$E,MATCH("Cb",'Global Parameter'!$A:$A,0)))&";" | D22: ="var Cb = "&IF(ISBLANK(INDEX('Global Parameter'!$D:$D,MATCH("Cb",'Global Parameter'!$A:$A,0))),"",INDEX('Global Parameter'!$D:$D,MATCH("Cb",'Global Parameter'!$A:$A,0)))&IF(ISBLANK(INDEX('Global Parameter'!$B:$B,MATCH("Cb",'Global Parameter'!$A:$A,0))),1,IF(INDEX('Global Parameter'!$B:$B,MATCH("Cb",'Global Parameter'!$A:$A,0))="",1,INDEX('Global Parameter'!$B:$B,MATCH("Cb",'Global Parameter'!$A:$A,0))))&IF(ISBLANK(INDEX('Global Parameter'!$E:$E,MATCH("Cb",'Global Parameter'!$A:$A,0))),"",INDEX('Global Parameter'!$E:$E,MATCH("Cb",'Global Parameter'!$A:$A,0)))&";"
B23: ="// --- this case" | C23: ="// --- this case" | D23: ="// --- this case"
B24: ="var draft = "&IF(ISBLANK(INDEX('Local Parameter'!$C:$C,MATCH("draft",'Local Parameter'!$A:$A,0))),"",INDEX('Local Parameter'!$C:$C,MATCH("draft",'Local Parameter'!$A:$A,0)))&IF(ISBLANK(INDEX('Local Parameter'!E:E,MATCH("draft",'Local Parameter'!$A:$A,0))),20.559,IF(INDEX('Local Parameter'!E:E,MATCH("draft",'Local Parameter'!$A:$A,0))="",20.559,INDEX('Local Parameter'!E:E,MATCH("draft",'Local Parameter'!$A:$A,0))))&IF(ISBLANK(INDEX('Local Parameter'!$D:$D,MATCH("draft",'Local Parameter'!$A:$A,0)))," m",IF(INDEX('Local Parameter'!$D:$D,MATCH("draft",'Local Parameter'!$A:$A,0))=""," m",INDEX('Local Parameter'!$D:$D,MATCH("draft",'Local Parameter'!$A:$A,0))))&";" | C24: ="var draft = "&IF(ISBLANK(INDEX('Local Parameter'!$C:$C,MATCH("draft",'Local Parameter'!$A:$A,0))),"",INDEX('Local Parameter'!$C:$C,MATCH("draft",'Local Parameter'!$A:$A,0)))&IF(ISBLANK(INDEX('Local Parameter'!F:F,MATCH("draft",'Local Parameter'!$A:$A,0))),20.559,IF(INDEX('Local Parameter'!F:F,MATCH("draft",'Local Parameter'!$A:$A,0))="",20.559,INDEX('Local Parameter'!F:F,MATCH("draft",'Local Parameter'!$A:$A,0))))&IF(ISBLANK(INDEX('Local Parameter'!$D:$D,MATCH("draft",'Local Parameter'!$A:$A,0)))," m",IF(INDEX('Local Parameter'!$D:$D,MATCH("draft",'Local Parameter'!$A:$A,0))=""," m",INDEX('Local Parameter'!$D:$D,MATCH("draft",'Local Parameter'!$A:$A,0))))&";" | D24: ="var draft = "&IF(ISBLANK(INDEX('Local Parameter'!$C:$C,MATCH("draft",'Local Parameter'!$A:$A,0))),"",INDEX('Local Parameter'!$C:$C,MATCH("draft",'Local Parameter'!$A:$A,0)))&IF(ISBLANK(INDEX('Local Parameter'!G:G,MATCH("draft",'Local Parameter'!$A:$A,0))),20.559,IF(INDEX('Local Parameter'!G:G,MATCH("draft",'Local Parameter'!$A:$A,0))="",20.559,INDEX('Local Parameter'!G:G,MATCH("draft",'Local Parameter'!$A:$A,0))))&IF(ISBLANK(INDEX('Local Parameter'!$D:$D,MATCH("draft",'Local Parameter'!$A:$A,0)))," m",IF(INDEX('Local Parameter'!$D:$D,MATCH("draft",'Local Parameter'!$A:$A,0))=""," m",INDEX('Local Parameter'!$D:$D,MATCH("draft",'Local Parameter'!$A:$A,0))))&";"
B25: ="var mu_deg = "&IF(ISBLANK(INDEX('Local Parameter'!$C:$C,MATCH("mu_deg",'Local Parameter'!$A:$A,0))),"",INDEX('Local Parameter'!$C:$C,MATCH("mu_deg",'Local Parameter'!$A:$A,0)))&IF(ISBLANK(INDEX('Local Parameter'!E:E,MATCH("mu_deg",'Local Parameter'!$A:$A,0))),90,IF(INDEX('Local Parameter'!E:E,MATCH("mu_deg",'Local Parameter'!$A:$A,0))="",90,INDEX('Local Parameter'!E:E,MATCH("mu_deg",'Local Parameter'!$A:$A,0))))&IF(ISBLANK(INDEX('Local Parameter'!$D:$D,MATCH("mu_deg",'Local Parameter'!$A:$A,0)))," deg",IF(INDEX('Local Parameter'!$D:$D,MATCH("mu_deg",'Local Parameter'!$A:$A,0))=""," deg",INDEX('Local Parameter'!$D:$D,MATCH("mu_deg",'Local Parameter'!$A:$A,0))))&";" | C25: ="var mu_deg = "&IF(ISBLANK(INDEX('Local Parameter'!$C:$C,MATCH("mu_deg",'Local Parameter'!$A:$A,0))),"",INDEX('Local Parameter'!$C:$C,MATCH("mu_deg",'Local Parameter'!$A:$A,0)))&IF(ISBLANK(INDEX('Local Parameter'!F:F,MATCH("mu_deg",'Local Parameter'!$A:$A,0))),90,IF(INDEX('Local Parameter'!F:F,MATCH("mu_deg",'Local Parameter'!$A:$A,0))="",90,INDEX('Local Parameter'!F:F,MATCH("mu_deg",'Local Parameter'!$A:$A,0))))&IF(ISBLANK(INDEX('Local Parameter'!$D:$D,MATCH("mu_deg",'Local Parameter'!$A:$A,0)))," deg",IF(INDEX('Local Parameter'!$D:$D,MATCH("mu_deg",'Local Parameter'!$A:$A,0))=""," deg",INDEX('Local Parameter'!$D:$D,MATCH("mu_deg",'Local Parameter'!$A:$A,0))))&";" | D25: ="var mu_deg = "&IF(ISBLANK(INDEX('Local Parameter'!$C:$C,MATCH("mu_deg",'Local Parameter'!$A:$A,0))),"",INDEX('Local Parameter'!$C:$C,MATCH("mu_deg",'Local Parameter'!$A:$A,0)))&IF(ISBLANK(INDEX('Local Parameter'!G:G,MATCH("mu_deg",'Local Parameter'!$A:$A,0))),90,IF(INDEX('Local Parameter'!G:G,MATCH("mu_deg",'Local Parameter'!$A:$A,0))="",90,INDEX('Local Parameter'!G:G,MATCH("mu_deg",'Local Parameter'!$A:$A,0))))&IF(ISBLANK(INDEX('Local Parameter'!$D:$D,MATCH("mu_deg",'Local Parameter'!$A:$A,0)))," deg",IF(INDEX('Local Parameter'!$D:$D,MATCH("mu_deg",'Local Parameter'!$A:$A,0))=""," deg",INDEX('Local Parameter'!$D:$D,MATCH("mu_deg",'Local Parameter'!$A:$A,0))))&";"
B26: ="var k_c = "&IF(ISBLANK(INDEX('Local Parameter'!$C:$C,MATCH("k_c",'Local Parameter'!$A:$A,0))),"",INDEX('Local Parameter'!$C:$C,MATCH("k_c",'Local Parameter'!$A:$A,0)))&IF(ISBLANK(INDEX('Local Parameter'!E:E,MATCH("k_c",'Local Parameter'!$A:$A,0))),1,IF(INDEX('Local Parameter'!E:E,MATCH("k_c",'Local Parameter'!$A:$A,0))="",1,INDEX('Local Parameter'!E:E,MATCH("k_c",'Local Parameter'!$A:$A,0))))&IF(ISBLANK(INDEX('Local Parameter'!$D:$D,MATCH("k_c",'Local Parameter'!$A:$A,0))),"",INDEX('Local Parameter'!$D:$D,MATCH("k_c",'Local Parameter'!$A:$A,0)))&";" | C26: ="var k_c = "&IF(ISBLANK(INDEX('Local Parameter'!$C:$C,MATCH("k_c",'Local Parameter'!$A:$A,0))),"",INDEX('Local Parameter'!$C:$C,MATCH("k_c",'Local Parameter'!$A:$A,0)))&IF(ISBLANK(INDEX('Local Parameter'!F:F,MATCH("k_c",'Local Parameter'!$A:$A,0))),1,IF(INDEX('Local Parameter'!F:F,MATCH("k_c",'Local Parameter'!$A:$A,0))="",1,INDEX('Local Parameter'!F:F,MATCH("k_c",'Local Parameter'!$A:$A,0))))&IF(ISBLANK(INDEX('Local Parameter'!$D:$D,MATCH("k_c",'Local Parameter'!$A:$A,0))),"",INDEX('Local Parameter'!$D:$D,MATCH("k_c",'Local Parameter'!$A:$A,0)))&";" | D26: ="var k_c = "&IF(ISBLANK(INDEX('Local Parameter'!$C:$C,MATCH("k_c",'Local Parameter'!$A:$A,0))),"",INDEX('Local Parameter'!$C:$C,MATCH("k_c",'Local Parameter'!$A:$A,0)))&IF(ISBLANK(INDEX('Local Parameter'!G:G,MATCH("k_c",'Local Parameter'!$A:$A,0))),1,IF(INDEX('Local Parameter'!G:G,MATCH("k_c",'Local Parameter'!$A:$A,0))="",1,INDEX('Local Parameter'!G:G,MATCH("k_c",'Local Parameter'!$A:$A,0))))&IF(ISBLANK(INDEX('Local Parameter'!$D:$D,MATCH("k_c",'Local Parameter'!$A:$A,0))),"",INDEX('Local Parameter'!$D:$D,MATCH("k_c",'Local Parameter'!$A:$A,0)))&";"
B27: ="var k_f0 = "&IF(ISBLANK(INDEX('Local Parameter'!$C:$C,MATCH("k_f0",'Local Parameter'!$A:$A,0))),"",INDEX('Local Parameter'!$C:$C,MATCH("k_f0",'Local Parameter'!$A:$A,0)))&IF(ISBLANK(INDEX('Local Parameter'!E:E,MATCH("k_f0",'Local Parameter'!$A:$A,0))),1,IF(INDEX('Local Parameter'!E:E,MATCH("k_f0",'Local Parameter'!$A:$A,0))="",1,INDEX('Local Parameter'!E:E,MATCH("k_f0",'Local Parameter'!$A:$A,0))))&IF(ISBLANK(INDEX('Local Parameter'!$D:$D,MATCH("k_f0",'Local Parameter'!$A:$A,0))),"",INDEX('Local Parameter'!$D:$D,MATCH("k_f0",'Local Parameter'!$A:$A,0)))&";" | C27: ="var k_f0 = "&IF(ISBLANK(INDEX('Local Parameter'!$C:$C,MATCH("k_f0",'Local Parameter'!$A:$A,0))),"",INDEX('Local Parameter'!$C:$C,MATCH("k_f0",'Local Parameter'!$A:$A,0)))&IF(ISBLANK(INDEX('Local Parameter'!F:F,MATCH("k_f0",'Local Parameter'!$A:$A,0))),1,IF(INDEX('Local Parameter'!F:F,MATCH("k_f0",'Local Parameter'!$A:$A,0))="",1,INDEX('Local Parameter'!F:F,MATCH("k_f0",'Local Parameter'!$A:$A,0))))&IF(ISBLANK(INDEX('Local Parameter'!$D:$D,MATCH("k_f0",'Local Parameter'!$A:$A,0))),"",INDEX('Local Parameter'!$D:$D,MATCH("k_f0",'Local Parameter'!$A:$A,0)))&";" | D27: ="var k_f0 = "&IF(ISBLANK(INDEX('Local Parameter'!$C:$C,MATCH("k_f0",'Local Parameter'!$A:$A,0))),"",INDEX('Local Parameter'!$C:$C,MATCH("k_f0",'Local Parameter'!$A:$A,0)))&IF(ISBLANK(INDEX('Local Parameter'!G:G,MATCH("k_f0",'Local Parameter'!$A:$A,0))),1,IF(INDEX('Local Parameter'!G:G,MATCH("k_f0",'Local Parameter'!$A:$A,0))="",1,INDEX('Local Parameter'!G:G,MATCH("k_f0",'Local Parameter'!$A:$A,0))))&IF(ISBLANK(INDEX('Local Parameter'!$D:$D,MATCH("k_f0",'Local Parameter'!$A:$A,0))),"",INDEX('Local Parameter'!$D:$D,MATCH("k_f0",'Local Parameter'!$A:$A,0)))&";"
B28: ="var k_u = "&IF(ISBLANK(INDEX('Local Parameter'!$C:$C,MATCH("k_u",'Local Parameter'!$A:$A,0))),"",INDEX('Local Parameter'!$C:$C,MATCH("k_u",'Local Parameter'!$A:$A,0)))&IF(ISBLANK(INDEX('Local Parameter'!E:E,MATCH("k_u",'Local Parameter'!$A:$A,0))),1.1,IF(INDEX('Local Parameter'!E:E,MATCH("k_u",'Local Parameter'!$A:$A,0))="",1.1,INDEX('Local Parameter'!E:E,MATCH("k_u",'Local Parameter'!$A:$A,0))))&IF(ISBLANK(INDEX('Local Parameter'!$D:$D,MATCH("k_u",'Local Parameter'!$A:$A,0))),"",INDEX('Local Parameter'!$D:$D,MATCH("k_u",'Local Parameter'!$A:$A,0)))&";" | C28: ="var k_u = "&IF(ISBLANK(INDEX('Local Parameter'!$C:$C,MATCH("k_u",'Local Parameter'!$A:$A,0))),"",INDEX('Local Parameter'!$C:$C,MATCH("k_u",'Local Parameter'!$A:$A,0)))&IF(ISBLANK(INDEX('Local Parameter'!F:F,MATCH("k_u",'Local Parameter'!$A:$A,0))),1.1,IF(INDEX('Local Parameter'!F:F,MATCH("k_u",'Local Parameter'!$A:$A,0))="",1.1,INDEX('Local Parameter'!F:F,MATCH("k_u",'Local Parameter'!$A:$A,0))))&IF(ISBLANK(INDEX('Local Parameter'!$D:$D,MATCH("k_u",'Local Parameter'!$A:$A,0))),"",INDEX('Local Parameter'!$D:$D,MATCH("k_u",'Local Parameter'!$A:$A,0)))&";" | D28: ="var k_u = "&IF(ISBLANK(INDEX('Local Parameter'!$C:$C,MATCH("k_u",'Local Parameter'!$A:$A,0))),"",INDEX('Local Parameter'!$C:$C,MATCH("k_u",'Local Parameter'!$A:$A,0)))&IF(ISBLANK(INDEX('Local Parameter'!G:G,MATCH("k_u",'Local Parameter'!$A:$A,0))),1.1,IF(INDEX('Local Parameter'!G:G,MATCH("k_u",'Local Parameter'!$A:$A,0))="",1.1,INDEX('Local Parameter'!G:G,MATCH("k_u",'Local Parameter'!$A:$A,0))))&IF(ISBLANK(INDEX('Local Parameter'!$D:$D,MATCH("k_u",'Local Parameter'!$A:$A,0))),"",INDEX('Local Parameter'!$D:$D,MATCH("k_u",'Local Parameter'!$A:$A,0)))&";"
B29: ="var beta_EPS = "&IF(ISBLANK(INDEX('Local Parameter'!$C:$C,MATCH("beta_EPS",'Local Parameter'!$A:$A,0))),"",INDEX('Local Parameter'!$C:$C,MATCH("beta_EPS",'Local Parameter'!$A:$A,0)))&IF(ISBLANK(INDEX('Local Parameter'!E:E,MATCH("beta_EPS",'Local Parameter'!$A:$A,0))),0.733,IF(INDEX('Local Parameter'!E:E,MATCH("beta_EPS",'Local Parameter'!$A:$A,0))="",0.733,INDEX('Local Parameter'!E:E,MATCH("beta_EPS",'Local Parameter'!$A:$A,0))))&IF(ISBLANK(INDEX('Local Parameter'!$D:$D,MATCH("beta_EPS",'Local Parameter'!$A:$A,0))),"",INDEX('Local Parameter'!$D:$D,MATCH("beta_EPS",'Local Parameter'!$A:$A,0)))&";" | C29: ="var beta_EPS = "&IF(ISBLANK(INDEX('Local Parameter'!$C:$C,MATCH("beta_EPS",'Local Parameter'!$A:$A,0))),"",INDEX('Local Parameter'!$C:$C,MATCH("beta_EPS",'Local Parameter'!$A:$A,0)))&IF(ISBLANK(INDEX('Local Parameter'!F:F,MATCH("beta_EPS",'Local Parameter'!$A:$A,0))),0.733,IF(INDEX('Local Parameter'!F:F,MATCH("beta_EPS",'Local Parameter'!$A:$A,0))="",0.733,INDEX('Local Parameter'!F:F,MATCH("beta_EPS",'Local Parameter'!$A:$A,0))))&IF(ISBLANK(INDEX('Local Parameter'!$D:$D,MATCH("beta_EPS",'Local Parameter'!$A:$A,0))),"",INDEX('Local Parameter'!$D:$D,MATCH("beta_EPS",'Local Parameter'!$A:$A,0)))&";" | D29: ="var beta_EPS = "&IF(ISBLANK(INDEX('Local Parameter'!$C:$C,MATCH("beta_EPS",'Local Parameter'!$A:$A,0))),"",INDEX('Local Parameter'!$C:$C,MATCH("beta_EPS",'Local Parameter'!$A:$A,0)))&IF(ISBLANK(INDEX('Local Parameter'!G:G,MATCH("beta_EPS",'Local Parameter'!$A:$A,0))),0.733,IF(INDEX('Local Parameter'!G:G,MATCH("beta_EPS",'Local Parameter'!$A:$A,0))="",0.733,INDEX('Local Parameter'!G:G,MATCH("beta_EPS",'Local Parameter'!$A:$A,0))))&IF(ISBLANK(INDEX('Local Parameter'!$D:$D,MATCH("beta_EPS",'Local Parameter'!$A:$A,0))),"",INDEX('Local Parameter'!$D:$D,MATCH("beta_EPS",'Local Parameter'!$A:$A,0)))&";"
B30: ="var beta_EPP = "&IF(ISBLANK(INDEX('Local Parameter'!$C:$C,MATCH("beta_EPP",'Local Parameter'!$A:$A,0))),"",INDEX('Local Parameter'!$C:$C,MATCH("beta_EPP",'Local Parameter'!$A:$A,0)))&IF(ISBLANK(INDEX('Local Parameter'!E:E,MATCH("beta_EPP",'Local Parameter'!$A:$A,0))),0.733,IF(INDEX('Local Parameter'!E:E,MATCH("beta_EPP",'Local Parameter'!$A:$A,0))="",0.733,INDEX('Local Parameter'!E:E,MATCH("beta_EPP",'Local Parameter'!$A:$A,0))))&IF(ISBLANK(INDEX('Local Parameter'!$D:$D,MATCH("beta_EPP",'Local Parameter'!$A:$A,0))),"",INDEX('Local Parameter'!$D:$D,MATCH("beta_EPP",'Local Parameter'!$A:$A,0)))&";" | C30: ="var beta_EPP = "&IF(ISBLANK(INDEX('Local Parameter'!$C:$C,MATCH("beta_EPP",'Local Parameter'!$A:$A,0))),"",INDEX('Local Parameter'!$C:$C,MATCH("beta_EPP",'Local Parameter'!$A:$A,0)))&IF(ISBLANK(INDEX('Local Parameter'!F:F,MATCH("beta_EPP",'Local Parameter'!$A:$A,0))),0.733,IF(INDEX('Local Parameter'!F:F,MATCH("beta_EPP",'Local Parameter'!$A:$A,0))="",0.733,INDEX('Local Parameter'!F:F,MATCH("beta_EPP",'Local Parameter'!$A:$A,0))))&IF(ISBLANK(INDEX('Local Parameter'!$D:$D,MATCH("beta_EPP",'Local Parameter'!$A:$A,0))),"",INDEX('Local Parameter'!$D:$D,MATCH("beta_EPP",'Local Parameter'!$A:$A,0)))&";" | D30: ="var beta_EPP = "&IF(ISBLANK(INDEX('Local Parameter'!$C:$C,MATCH("beta_EPP",'Local Parameter'!$A:$A,0))),"",INDEX('Local Parameter'!$C:$C,MATCH("beta_EPP",'Local Parameter'!$A:$A,0)))&IF(ISBLANK(INDEX('Local Parameter'!G:G,MATCH("beta_EPP",'Local Parameter'!$A:$A,0))),0.733,IF(INDEX('Local Parameter'!G:G,MATCH("beta_EPP",'Local Parameter'!$A:$A,0))="",0.733,INDEX('Local Parameter'!G:G,MATCH("beta_EPP",'Local Parameter'!$A:$A,0))))&IF(ISBLANK(INDEX('Local Parameter'!$D:$D,MATCH("beta_EPP",'Local Parameter'!$A:$A,0))),"",INDEX('Local Parameter'!$D:$D,MATCH("beta_EPP",'Local Parameter'!$A:$A,0)))&";"
B31: ="var k_esf = "&IF(ISBLANK(INDEX('Local Parameter'!$C:$C,MATCH("k_esf",'Local Parameter'!$A:$A,0))),"",INDEX('Local Parameter'!$C:$C,MATCH("k_esf",'Local Parameter'!$A:$A,0)))&IF(ISBLANK(INDEX('Local Parameter'!E:E,MATCH("k_esf",'Local Parameter'!$A:$A,0))),1.1,IF(INDEX('Local Parameter'!E:E,MATCH("k_esf",'Local Parameter'!$A:$A,0))="",1.1,INDEX('Local Parameter'!E:E,MATCH("k_esf",'Local Parameter'!$A:$A,0))))&IF(ISBLANK(INDEX('Local Parameter'!$D:$D,MATCH("k_esf",'Local Parameter'!$A:$A,0))),"",INDEX('Local Parameter'!$D:$D,MATCH("k_esf",'Local Parameter'!$A:$A,0)))&";" | C31: ="var k_esf = "&IF(ISBLANK(INDEX('Local Parameter'!$C:$C,MATCH("k_esf",'Local Parameter'!$A:$A,0))),"",INDEX('Local Parameter'!$C:$C,MATCH("k_esf",'Local Parameter'!$A:$A,0)))&IF(ISBLANK(INDEX('Local Parameter'!F:F,MATCH("k_esf",'Local Parameter'!$A:$A,0))),1.1,IF(INDEX('Local Parameter'!F:F,MATCH("k_esf",'Local Parameter'!$A:$A,0))="",1.1,INDEX('Local Parameter'!F:F,MATCH("k_esf",'Local Parameter'!$A:$A,0))))&IF(ISBLANK(INDEX('Local Parameter'!$D:$D,MATCH("k_esf",'Local Parameter'!$A:$A,0))),"",INDEX('Local Parameter'!$D:$D,MATCH("k_esf",'Local Parameter'!$A:$A,0)))&";" | D31: ="var k_esf = "&IF(ISBLANK(INDEX('Local Parameter'!$C:$C,MATCH("k_esf",'Local Parameter'!$A:$A,0))),"",INDEX('Local Parameter'!$C:$C,MATCH("k_esf",'Local Parameter'!$A:$A,0)))&IF(ISBLANK(INDEX('Local Parameter'!G:G,MATCH("k_esf",'Local Parameter'!$A:$A,0))),1.1,IF(INDEX('Local Parameter'!G:G,MATCH("k_esf",'Local Parameter'!$A:$A,0))="",1.1,INDEX('Local Parameter'!G:G,MATCH("k_esf",'Local Parameter'!$A:$A,0))))&IF(ISBLANK(INDEX('Local Parameter'!$D:$D,MATCH("k_esf",'Local Parameter'!$A:$A,0))),"",INDEX('Local Parameter'!$D:$D,MATCH("k_esf",'Local Parameter'!$A:$A,0)))&";"
B32: ="var x_o = "&IF(ISBLANK(INDEX('Local Parameter'!$C:$C,MATCH("x_o",'Local Parameter'!$A:$A,0))),"",INDEX('Local Parameter'!$C:$C,MATCH("x_o",'Local Parameter'!$A:$A,0)))&IF(ISBLANK(INDEX('Local Parameter'!E:E,MATCH("x_o",'Local Parameter'!$A:$A,0))),51,IF(INDEX('Local Parameter'!E:E,MATCH("x_o",'Local Parameter'!$A:$A,0))="",51,INDEX('Local Parameter'!E:E,MATCH("x_o",'Local Parameter'!$A:$A,0))))&IF(ISBLANK(INDEX('Local Parameter'!$D:$D,MATCH("x_o",'Local Parameter'!$A:$A,0)))," m",IF(INDEX('Local Parameter'!$D:$D,MATCH("x_o",'Local Parameter'!$A:$A,0))=""," m",INDEX('Local Parameter'!$D:$D,MATCH("x_o",'Local Parameter'!$A:$A,0))))&";" | C32: ="var x_o = "&IF(ISBLANK(INDEX('Local Parameter'!$C:$C,MATCH("x_o",'Local Parameter'!$A:$A,0))),"",INDEX('Local Parameter'!$C:$C,MATCH("x_o",'Local Parameter'!$A:$A,0)))&IF(ISBLANK(INDEX('Local Parameter'!F:F,MATCH("x_o",'Local Parameter'!$A:$A,0))),51,IF(INDEX('Local Parameter'!F:F,MATCH("x_o",'Local Parameter'!$A:$A,0))="",51,INDEX('Local Parameter'!F:F,MATCH("x_o",'Local Parameter'!$A:$A,0))))&IF(ISBLANK(INDEX('Local Parameter'!$D:$D,MATCH("x_o",'Local Parameter'!$A:$A,0)))," m",IF(INDEX('Local Parameter'!$D:$D,MATCH("x_o",'Local Parameter'!$A:$A,0))=""," m",INDEX('Local Parameter'!$D:$D,MATCH("x_o",'Local Parameter'!$A:$A,0))))&";" | D32: ="var x_o = "&IF(ISBLANK(INDEX('Local Parameter'!$C:$C,MATCH("x_o",'Local Parameter'!$A:$A,0))),"",INDEX('Local Parameter'!$C:$C,MATCH("x_o",'Local Parameter'!$A:$A,0)))&IF(ISBLANK(INDEX('Local Parameter'!G:G,MATCH("x_o",'Local Parameter'!$A:$A,0))),51,IF(INDEX('Local Parameter'!G:G,MATCH("x_o",'Local Parameter'!$A:$A,0))="",51,INDEX('Local Parameter'!G:G,MATCH("x_o",'Local Parameter'!$A:$A,0))))&IF(ISBLANK(INDEX('Local Parameter'!$D:$D,MATCH("x_o",'Local Parameter'!$A:$A,0)))," m",IF(INDEX('Local Parameter'!$D:$D,MATCH("x_o",'Local Parameter'!$A:$A,0))=""," m",INDEX('Local Parameter'!$D:$D,MATCH("x_o",'Local Parameter'!$A:$A,0))))&";"
B33: ="// --- the calculation" | C33: ="// --- the calculation" | D33: ="// --- the calculation"
B34: ="var u = mu_deg; // the heading, as an Angle -- cos/sin take it directly" | C34: ="var u = mu_deg; // the heading, as an Angle -- cos/sin take it directly" | D34: ="var u = mu_deg; // the heading, as an Angle -- cos/sin take it directly"
B35: ="var C_1 = 0; // wave coefficient, 0 until a length bracket matches" | C35: ="var C_1 = 0; // wave coefficient, 0 until a length bracket matches" | D35: ="var C_1 = 0; // wave coefficient, 0 until a length bracket matches"
B36: ="// C_1 brackets of 3-2-1/3.5, closed at both ends; outside them C_1 is zero" | C36: ="// C_1 brackets of 3-2-1/3.5, closed at both ends; outside them C_1 is zero" | D36: ="// C_1 brackets of 3-2-1/3.5, closed at both ends; outside them C_1 is zero"
B37: ="if (L >= 61 m && L <= 90 m ) C_1 = 0.044 * (L / 1 m) + 3.75;" | C37: ="if (L >= 61 m && L <= 90 m ) C_1 = 0.044 * (L / 1 m) + 3.75;" | D37: ="if (L >= 61 m && L <= 90 m ) C_1 = 0.044 * (L / 1 m) + 3.75;"
B38: ="else if (L > 90 m && L < 300 m) C_1 = 10.75 - Math.pow((300 m - L) / 100 m, 1.5);" | C38: ="else if (L > 90 m && L < 300 m) C_1 = 10.75 - Math.pow((300 m - L) / 100 m, 1.5);" | D38: ="else if (L > 90 m && L < 300 m) C_1 = 10.75 - Math.pow((300 m - L) / 100 m, 1.5);"
B39: ="else if (L >= 300 m && L < 350 m) C_1 = 10.75;" | C39: ="else if (L >= 300 m && L < 350 m) C_1 = 10.75;" | D39: ="else if (L >= 300 m && L < 350 m) C_1 = 10.75;"
B40: ="else if (L >= 350 m && L <= 500 m) C_1 = 10.75 - Math.pow((L - 350 m) / 150 m, 1.5);" | C40: ="else if (L >= 350 m && L <= 500 m) C_1 = 10.75 - Math.pow((L - 350 m) / 150 m, 1.5);" | D40: ="else if (L >= 350 m && L <= 500 m) C_1 = 10.75 - Math.pow((L - 350 m) / 150 m, 1.5);"
...

Sheet Summary EXT
